<?xml version="1.0" ?>
<!-- This URDF was automatically created by SolidWorks to URDF Exporter! Originally created by Stephen Brawner (brawner@gmail.com) 
     Commit Version: 1.6.0-1-g15f4949  Build Version: 1.6.7594.29634
     For more information, please see http://wiki.ros.org/sw_urdf_exporter -->
<robot name="bot_urdf">
<!--################################# BASE #####################################-->
  <link name="base_link">
    <inertial>
      <origin
        xyz="0.0030946 4.78250032638821E-11 0.053305"
        rpy="0 0 0" />
      <mass
        value="47.873" />
      <inertia
        ixx="0.774276574699151"
        ixy="-1.03781944357671E-10"
        ixz="0.00763014265820928"
        iyy="1.64933255189991"
        iyz="1.09578155845563E-12"
        izz="2.1239326987473" />
    </inertial>
    <visual>
      <origin
        xyz="0 0 0"
        rpy="1.5707963267949 0 3.14" />
      <geometry>
        <mesh filename="package://mobile_manipulator_full/meshes/robot_base.stl" />
      </geometry>
      <material
        name="">
        <color
          rgba="0.79216 0.81961 0.93333 1" />
      </material>
    </visual>
    <collision>
      <origin
        xyz="0 0 0"
        rpy="1.5707963267949 0 3.14" />
      <geometry>
        <mesh filename="package://mobile_manipulator_full/meshes/robot_base.stl" />
      </geometry>
    </collision>
  </link>

<link name="front_left_wheel">
    <inertial>
      <origin
        xyz="-4.1867E-18 0.0068085 -1.65658661799998E-18"
        rpy="0 0 0" />
      <mass
        value="2.6578" />
      <inertia
        ixx="0.00856502765719703"
        ixy="1.5074118157338E-19"
        ixz="-4.78150098725052E-19"
        iyy="0.013670640432096"
        iyz="-2.68136447099727E-19"
        izz="0.00856502765719703" />
    </inertial>
    <visual>
      <origin
        xyz="0 0 0"
        rpy="1.5707963267949 0 0" />
      <geometry>
        <mesh filename="package://mobile_manipulator_full/meshes/wheel.stl" />
      </geometry>
      <material
        name="">
        <color
          rgba="0.79216 0.81961 0.93333 1" />
      </material>
    </visual>
    <collision>
      <origin
        xyz="0 0 0"
        rpy="1.5707963267949 0 0" />
      <geometry>
        <mesh filename="package://mobile_manipulator_full/meshes/wheel.stl" />
      </geometry>
    </collision>
  </link>

<link name="front_right_wheel">
    <inertial>
      <origin
        xyz="-4.1867E-18 0.0068085 -1.65658661799998E-18"
        rpy="0 0 0" />
      <mass
        value="2.6578" />
      <inertia
        ixx="0.00856502765719703"
        ixy="1.5074118157338E-19"
        ixz="-4.78150098725052E-19"
        iyy="0.013670640432096"
        iyz="-2.68136447099727E-19"
        izz="0.00856502765719703" />
    </inertial>
    <visual>
      <origin
        xyz="0 0 0"
        rpy="1.5707963267949 0 0" />
      <geometry>
        <mesh filename="package://mobile_manipulator_full/meshes/wheel.stl" />
      </geometry>
      <material
        name="">
        <color
          rgba="0.79216 0.81961 0.93333 1" />
      </material>
    </visual>
    <collision>
      <origin
        xyz="0 0 0"
        rpy="1.5707963267949 0 0" />
      <geometry>
        <mesh filename="package://mobile_manipulator_full/meshes/wheel.stl" />
      </geometry>
    </collision>
  </link>

<link name="rear_left_wheel">
    <inertial>
      <origin
        xyz="-4.1867E-18 0.0068085 -1.65658661799998E-18"
        rpy="0 0 0" />
      <mass
        value="2.6578" />
      <inertia
        ixx="0.00856502765719703"
        ixy="1.5074118157338E-19"
        ixz="-4.78150098725052E-19"
        iyy="0.013670640432096"
        iyz="-2.68136447099727E-19"
        izz="0.00856502765719703" />
    </inertial>
    <visual>
      <origin
        xyz="0 0 0"
        rpy="1.5707963267949 0 0" />
      <geometry>
        <mesh filename="package://mobile_manipulator_full/meshes/wheel.stl" />
      </geometry>
      <material
        name="">
        <color
          rgba="0.79216 0.81961 0.93333 1" />
      </material>
    </visual>
    <collision>
      <origin
        xyz="0 0 0"
        rpy="1.5707963267949 0 0" />
      <geometry>
        <mesh filename="package://mobile_manipulator_full/meshes/wheel.stl" />
      </geometry>
    </collision>
  </link>

<link name="rear_right_wheel">
    <inertial>
      <origin
        xyz="-4.1867E-18 0.0068085 -1.65658661799998E-18"
        rpy="0 0 0" />
      <mass
        value="2.6578" />
      <inertia
        ixx="0.00856502765719703"
        ixy="1.5074118157338E-19"
        ixz="-4.78150098725052E-19"
        iyy="0.013670640432096"
        iyz="-2.68136447099727E-19"
        izz="0.00856502765719703" />
    </inertial>
    <visual>
      <origin
        xyz="0 0 0"
        rpy="1.5707963267949 0 0" />
      <geometry>
        <mesh filename="package://mobile_manipulator_full/meshes/wheel.stl" />
      </geometry>
      <material
        name="">
        <color
          rgba="0.79216 0.81961 0.93333 1" />
      </material>
    </visual>
    <collision>
      <origin
        xyz="0 0 0"
        rpy="1.5707963267949 0 0" />
      <geometry>
        <mesh filename="package://mobile_manipulator_full/meshes/wheel.stl" />
      </geometry>
    </collision>
  </link>


<joint name="front_left_wheel_joint" type="continuous">
    <axis xyz="0 1 0"/>
    <parent link ="base_link"/>
    <child link ="front_left_wheel"/>
    <origin rpy ="0 0 0" xyz= "0.220 0.250 0"/>
  </joint>


<joint name="front_right_wheel_joint" type="continuous">
    <axis xyz="0 1 0"/>
    <parent link ="base_link"/>
    <child link ="front_right_wheel"/>
    <origin rpy ="0 0 0" xyz= "0.220 -0.250 0"/>
  </joint>

<joint name="rear_left_wheel_joint" type="continuous">
    <axis xyz="0 1 0"/>
    <parent link ="base_link"/>
    <child link ="rear_left_wheel"/>
    <origin rpy ="0 0 0" xyz= "-0.220 0.250 0"/>
  </joint>

<joint name="rear_right_wheel_joint" type="continuous">
    <axis xyz="0 1 0"/>
    <parent link ="base_link"/>
    <child link ="rear_right_wheel"/>
    <origin rpy ="0 0 0" xyz= "-0.220 -0.250 0"/>
</joint>

<link
    name="link1">
    <inertial>
      <origin
        xyz="-4.1633E-17 -0.015131 5.5511E-17"
        rpy="0 0 0" />
      <mass
        value="0.023096" />
      <inertia
        ixx="7.7159E-06"
        ixy="-7.765E-22"
        ixz="6.2782E-12"
        iyy="3.045E-06"
        iyz="2.4595E-22"
        izz="6.7506E-06" />
    </inertial>
    <visual>
      <origin
        xyz="0 0 0"
        rpy="0 0 0" />
      <geometry>
        <mesh
          filename="package://mobile_manipulator_full/meshes/link1.STL" />
      </geometry>
      <material
        name="">
        <color
          rgba="0.79216 0.81961 0.93333 1" />
      </material>
    </visual>
    <collision>
      <origin
        xyz="0 0 0"
        rpy="0 0 0" />
      <geometry>
        <mesh
          filename="package://mobile_manipulator_full/meshes/link1.STL" />
      </geometry>
    </collision>
  </link>
  <joint
    name="j0"
    type="continuous">
    <origin
      xyz="0.029886 0 -0.023094"
      rpy="1.5708 0 0.010779" />
    <parent
      link="base_link" />
    <child
      link="link1" />
    <axis
      xyz="0 1 0" />
  </joint>
 <link
    name="link2">
    <inertial>
      <origin
        xyz="0.098154 3.4694E-18 -0.0010515"
        rpy="0 0 0" />
      <mass
        value="0.06328" />
      <inertia
        ixx="3.1999E-06"
        ixy="1.3107E-22"
        ixz="1.3351E-19"
        iyy="0.00025364"
        iyz="-2.8233E-22"
        izz="0.00025356" />
    </inertial>
    <visual>
      <origin
        xyz="0 0 0"
        rpy="0 0 0" />
      <geometry>
        <mesh
          filename="package://mobile_manipulator_full/meshes/link2.STL" />
      </geometry>
      <material
        name="">
        <color
          rgba="0.79216 0.81961 0.93333 1" />
      </material>
    </visual>
    <collision>
      <origin
        xyz="0 0 0"
        rpy="0 0 0" />
      <geometry>
        <mesh
          filename="package://mobile_manipulator_full/meshes/link2.STL" />
      </geometry>
    </collision>
  </link>
  <joint
    name="j1"
    type="continuous">
    <origin
      xyz="0.168 0.17 0"
      rpy="-1.5708 0 1.3202" />
    <parent
      link="link1" />
    <child
      link="link2" />
    <axis
      xyz="0 1 0" />
  </joint>
<link
    name="link3">
    <inertial>
      <origin
        xyz="0.14646 5.5511E-17 6.9389E-18"
        rpy="0 0 0" />
      <mass
        value="0.085316" />
      <inertia
        ixx="1.8615E-05"
        ixy="1.0969E-19"
        ixz="3.3102E-20"
        iyy="0.00065653"
        iyz="8.3934E-21"
        izz="0.00064157" />
    </inertial>
    <visual>
      <origin
        xyz="0 0 0"
        rpy="0 0 0" />
      <geometry>
        <mesh
          filename="package://mobile_manipulator_full/meshes/link3.STL" />
      </geometry>
      <material
        name="">
        <color
          rgba="0.79216 0.81961 0.93333 1" />
      </material>
    </visual>
    <collision>
      <origin
        xyz="0 0 0"
        rpy="0 0 0" />
      <geometry>
        <mesh
          filename="package://mobile_manipulator_full/meshes/link3.STL" />
      </geometry>
    </collision>
  </link>
  <joint
    name="j2"
    type="continuous">
    <origin
      xyz="0.19815 0 -0.0010515"
      rpy="1.5708 0.79123 0" />
    <parent
      link="link2" />
    <child
      link="link3" />
    <axis
      xyz="0 0 1" />
  </joint>
<transmission name="front_left_wheel_trans" type="SimpleTransmission">
  <type>transmission_interface/SimpleTransmission</type>
  <actuator name="front_left_wheel_motor">
   <hardwareInterface>hardware_interface/VelocityJointInterface</hardwareInterface>
   <mechanicalReduction>1</mechanicalReduction>
  </actuator>
  <joint name="front_left_wheel_joint">
   <hardwareInterface>hardware_interface/VelocityJointInterface</hardwareInterface>
  </joint>
</transmission>

<transmission name="front_right_wheel_trans" type="SimpleTransmission">
  <type>transmission_interface/SimpleTransmission</type>
  <actuator name="front_right_wheel_motor">
   <hardwareInterface>hardware_interface/VelocityJointInterface</hardwareInterface>
   <mechanicalReduction>1</mechanicalReduction>
  </actuator>
  <joint name="front_right_wheel_joint">
   <hardwareInterface>hardware_interface/VelocityJointInterface</hardwareInterface>
  </joint>
</transmission>

<transmission name="rear_left_wheel_trans" type="SimpleTransmission">
  <type>transmission_interface/SimpleTransmission</type>
  <actuator name="rear_left_wheel_motor">
   <hardwareInterface>hardware_interface/VelocityJointInterface</hardwareInterface>
   <mechanicalReduction>1</mechanicalReduction>
  </actuator>
  <joint name="rear_left_wheel_joint">
   <hardwareInterface>hardware_interface/VelocityJointInterface</hardwareInterface>
  </joint>
</transmission>

<transmission name="rear_right_wheel_trans" type="SimpleTransmission">
  <type>transmission_interface/SimpleTransmission</type>
  <actuator name="rear_right_wheel_motor">
   <hardwareInterface>hardware_interface/VelocityJointInterface</hardwareInterface>
   <mechanicalReduction>1</mechanicalReduction>
  </actuator>
  <joint name="rear_right_wheel_joint">
   <hardwareInterface>hardware_interface/VelocityJointInterface</hardwareInterface>
  </joint>
</transmission>
<!--################################ ARM TRANSIMISSIONS ######################################-->
<transmission name="j0_trans" type="SimpleTransmission">
  <type>transmission_interface/SimpleTransmission</type>
  <actuator name="j0_motor">
   <hardwareInterface>hardware_interface/PositionJointInterface</hardwareInterface>
   <mechanicalReduction>1</mechanicalReduction>
  </actuator>
  <joint name="j0">
   <hardwareInterface>hardware_interface/PositionJointInterface</hardwareInterface>
  </joint>
</transmission>

<transmission name="j1_trans" type="SimpleTransmission">
  <type>transmission_interface/SimpleTransmission</type>
  <actuator name="j1_motor">
   <hardwareInterface>hardware_interface/PositionJointInterface</hardwareInterface>
   <mechanicalReduction>1</mechanicalReduction>
  </actuator>
  <joint name="j1">
   <hardwareInterface>hardware_interface/PositionJointInterface</hardwareInterface>
  </joint>
</transmission>

<transmission name="j2_trans" type="SimpleTransmission">
  <type>transmission_interface/SimpleTransmission</type>
  <actuator name="j2_motor">
   <hardwareInterface>hardware_interface/PositionJointInterface</hardwareInterface>
   <mechanicalReduction>1</mechanicalReduction>
  </actuator>
  <joint name="j2">
   <hardwareInterface>hardware_interface/PositionJointInterface</hardwareInterface>
  </joint>
</transmission>

<!--######################################################################-->
<gazebo>
    <plugin name="gazebo_ros_control" filename="libgazebo_ros_control.so">
      <robotNamespace>/</robotNamespace>
      <controlPeriod>0.001</controlPeriod>
      <legacyModeNS>false</legacyModeNS>
    </plugin>
  </gazebo>
<!--######################################################################-->
  <gazebo>
    <plugin name="joint_state_publisher" filename="libgazebo_ros_joint_state_publisher.so">
      <jointName>j0, j1,j2</jointName>
    </plugin>
  </gazebo>
<!--######################################################################-->

<!--######################################################################-->
<gazebo>
      <plugin name="diff_drive_controller" filename="libgazebo_ros_diff_drive.so">
        <legacyMode>false</legacyMode>
        <alwaysOn>true</alwaysOn>
        <updateRate>1000.0</updateRate>
        <leftJoint>front_left_wheel_joint, rear_left_wheel_joint</leftJoint>
        <rightJoint>front_right_wheel_joint, rear_right_wheel_joint</rightJoint>
        <wheelSeparation>0.5</wheelSeparation>
        <wheelDiameter>0.2</wheelDiameter>
        <wheelTorque>10</wheelTorque>
        <publishTf>1</publishTf>
        <odometryFrame>map</odometryFrame>
        <commandTopic>cmd_vel</commandTopic>
        <odometryTopic>odom</odometryTopic>
        <robotBaseFrame>base_link</robotBaseFrame>
        <wheelAcceleration>2.8</wheelAcceleration>
        <publishWheelJointState>true</publishWheelJointState>
        <publishWheelTF>false</publishWheelTF>
        <odometrySource>world</odometrySource>
        <rosDebugLevel>Debug</rosDebugLevel>
      </plugin>
</gazebo>
<!--######################################################################-->
<gazebo reference="front_left_wheel">
 <mu1 value="1.0"/>
 <mu2 value="1.0"/>
 <kp value="10000000.0" />
 <kd value="1.0" />
 <fdir1 value="1 0 0"/>
</gazebo>

<gazebo reference="front_right_wheel">
 <mu1 value="1.0"/>
 <mu2 value="1.0"/>
 <kp value="10000000.0" />
 <kd value="1.0" />
 <fdir1 value="1 0 0"/>
</gazebo>

<gazebo reference="rear_left_wheel">
 <mu1 value="1.0"/>
 <mu2 value="1.0"/>
 <kp value="10000000.0" />
 <kd value="1.0" />
 <fdir1 value="1 0 0"/>
</gazebo>

<gazebo reference="rear_left_wheel">
 <mu1 value="1.0"/>
 <mu2 value="1.0"/>
 <kp value="10000000.0" />
 <kd value="1.0" />
 <fdir1 value="1 0 0"/>
</gazebo>

</robot>
